<mujoco model="iiwa14">

	<option timestep='0.0001' iterations='50' integrator='Euler' collision='all' gravity="0 0 0"/>


    <asset>
        <texture type="skybox" builtin="flat" rgb1="1 1 1" rgb2="1 1 1" width="100" height="100" />
        <mesh name="iiwa14_link_0" file="meshes/link_0.stl" />
        <mesh name="iiwa14_link_1" file="meshes/link_1.stl" />
        <mesh name="iiwa14_link_2" file="meshes/link_2.stl" />
        <mesh name="iiwa14_link_3" file="meshes/link_3.stl" />
        <mesh name="iiwa14_link_4" file="meshes/link_4.stl" />
        <mesh name="iiwa14_link_5" file="meshes/link_5.stl" />
        <mesh name="iiwa14_link_6" file="meshes/link_6.stl" />
        <mesh name="iiwa14_link_7" file="meshes/link_7.stl" />
        <mesh name="iiwa14_link_0_vis" file="meshes/link_0.stl" />
        <mesh name="iiwa14_link_1_vis" file="meshes/link_1.stl" />
        <mesh name="iiwa14_link_2_vis" file="meshes/link_2.stl" />
        <mesh name="iiwa14_link_3_vis" file="meshes/link_3.stl" />
        <mesh name="iiwa14_link_4_vis" file="meshes/link_4.stl" />
        <mesh name="iiwa14_link_5_vis" file="meshes/link_5.stl" />
        <mesh name="iiwa14_link_6_vis" file="meshes/link_6.stl" />
        <mesh name="iiwa14_link_7_vis" file="meshes/link_7.stl" />
        <mesh file="meshes/pedestal.stl" name="pedestal"/>
    </asset>
    <worldbody>
            <body name="iiwa14_link_1" pos="0 0 0">
                <inertial pos="0 -0.03 0.12" quat="0.428904 0.562175 -0.562175 0.428904" mass="3.4525" diaginertia="0.0218946 0.02183 0.00663837" />
                <site     pos="0 -0.03 0.12" quat="0.428904 0.562175 -0.562175 0.428904" name="link1_COM" />
                <joint name="iiwa14_joint_1" pos="0 0 0" axis="0 0 1" limited="false" range="-2.96706 2.96706" damping="0.0" />
                <geom type="mesh" contype="0" conaffinity="0" group="1" rgba="0.4 0.4 0.4 1" name="iiwa14_link_1_visual" mesh="iiwa14_link_1_vis" />
                <geom type="mesh" contype="0" rgba="0.4 0.4 0.4 1" mesh="iiwa14_link_1" name="iiwa14_link_1_collision" />
                <body name="iiwa14_link_2" pos="0 0 0.2025" quat="0 0 0.707107 0.707107">
                    <inertial pos="0.0003 0.059 0.042" quat="0.701371 0.0898824 0.0898824 0.701371" mass="3.4821" diaginertia="0.02179 0.0217049 0.00684512" />
                    <site     pos="0.0003 0.059 0.042" quat="0.701371 0.0898824 0.0898824 0.701371" name="link2_COM" />
                    <joint name="iiwa14_joint_2" pos="0 0 0" axis="0 0 1" limited="false" range="-2.0944 2.0944" damping="0.0" />
                    <geom type="mesh" contype="0" conaffinity="0" group="1" rgba="1 0.423529 0.0392157 1" name="iiwa14_link_2_visual" mesh="iiwa14_link_2_vis" />
                    <geom type="mesh" contype="0" rgba="1 0.423529 0.0392157 1" mesh="iiwa14_link_2" name="iiwa14_link_2_collision" />
                    <body name="iiwa14_link_3" pos="0 0.2045 0" quat="0 0 0.707107 0.707107">
                        <inertial pos="0 0.03 0.13" quat="0.56292 0.427927 -0.427927 0.56292" mass="4.05623" diaginertia="0.0321488 0.03204 0.00799117" />
                        <site     pos="0 0.03 0.13" quat="0.56292 0.427927 -0.427927 0.56292" name="link3_COM" />
                        <joint name="iiwa14_joint_3" pos="0 0 0" axis="0 0 1" limited="false" range="-2.96706 2.96706" damping="0.0" />
                        <geom type="mesh" contype="0" conaffinity="0" group="1" rgba="0.4 0.4 0.4 1" name="iiwa14_link_3_visual" mesh="iiwa14_link_3_vis" />
                        <geom type="mesh" contype="0" rgba="0.4 0.4 0.4 1" mesh="iiwa14_link_3" name="iiwa14_link_3_collision" />
                        <body name="iiwa14_link_4" pos="0 0 0.2155" quat="0.707107 0.707107 0 0">
                            <inertial pos="0 0.067 0.034" quat="0.991887 -0.127124 0 0" mass="3.4822" diaginertia="0.02178 0.0216947 0.00684029" />
                            <site     pos="0 0.067 0.034" quat="0.991887 -0.127124 0 0" name="link4_COM" />
                            <joint name="iiwa14_joint_4" pos="0 0 0" axis="0 0 1" limited="false" range="-2.0944 2.0944" damping="0.0" />
                            <geom type="mesh" contype="0" conaffinity="0" group="1" rgba="1 0.423529 0.0392157 1" name="iiwa14_link_4_visual" mesh="iiwa14_link_4_vis" />
                            <geom type="mesh" contype="0" rgba="1 0.423529 0.0392157 1" mesh="iiwa14_link_4" name="iiwa14_link_4_collision" />
                            <body name="iiwa14_link_5" pos="0 0.1845 0" quat="0 0 0.707107 0.707107">
                                <inertial pos="0.0001 0.021 0.076" quat="0.365352 0.605407 -0.605407 0.365352" mass="2.1633" diaginertia="0.0131987 0.01287 0.0036293" />
                                <site     pos="0.0001 0.021 0.076" quat="0.365352 0.605407 -0.605407 0.365352" name="link5_COM" />
                                <joint name="iiwa14_joint_5" pos="0 0 0" axis="0 0 1" limited="false" range="-2.96706 2.96706" damping="0.0" />
                                <geom type="mesh" contype="0" conaffinity="0" group="1" rgba="0.4 0.4 0.4 1" name="iiwa14_link_5_visual" mesh="iiwa14_link_5_vis" />
                                <geom type="mesh" contype="0" rgba="0.4 0.4 0.4 1" mesh="iiwa14_link_5" name="iiwa14_link_5_collision" />
                                <body name="iiwa14_link_6" pos="0 0 0.2155" quat="0.707107 0.707107 0 0">
                                    <inertial pos="0 0.0006 0.0004" quat="0.996112 0.088097 0 0" mass="2.3466" diaginertia="0.006509 0.00631585 0.00447015" />
                                    <site     pos="0 0.0006 0.0004" quat="0.996112 0.088097 0 0" name="link6_COM" />
                                    <joint name="iiwa14_joint_6" pos="0 0 0" axis="0 0 1" limited="false" range="-2.0944 2.0944" damping="0.0" />
                                    <geom type="mesh" contype="0" conaffinity="0" group="1" mesh="iiwa14_link_6_vis" name="iiwa14_link_6_visual" rgba="1 0.423529 0.0392157 1" />
                                    <geom type="mesh" contype="0" rgba="1 0.423529 0.0392157 1" mesh="iiwa14_link_6" name="iiwa14_link_6_collision" />
                                    <body name="iiwa14_link_7" pos="0 0.081 0" quat="0.707107 -0.707107 0 0">
                                        <inertial pos="0 0 0.02" quat="0.923068 0 0 0.384636" mass="3.129" diaginertia="0.0152362 0.0140538 0.002872" />
                                        <site     pos="0 0 0.02" quat="0.923068 0 0 0.384636" name="link7_COM" />
                                        <joint name="iiwa14_joint_7" pos="0 0 0" axis="0 0 1" limited="false" range="-3.05433 3.05433" damping="0.0" />
                                        <geom type="mesh" contype="0" conaffinity="0" group="1" rgba="0.4 0.4 0.4 1" mesh="iiwa14_link_7_vis" name="iiwa14_link_7_visual" />
                                        <geom type="mesh" contype="0" rgba="0.4 0.4 0.4 1" mesh="iiwa14_link_7" name="iiwa14_link_7_collision" />
                                        <body name="iiwa14_right_hand" pos="0 0 0.045" quat="0 0 0 1">
                                            <!-- This camera points out from the eef. -->
                                            <camera mode="fixed" name="iiwa14_eye_in_hand" pos="0.05 0 0" quat="0 0.707108 0.707108 0" fovy="75"/>
                                            <!-- To add gripper -->
                                        </body>
                                    </body>
                                </body>
                            </body>
                        </body>
                    </body>
                </body>
            </body>
    </worldbody>

    <actuator>
        <!-- Physical limits of the actuator. -->
        <!-- Values taken from kuka_lbr_iiwa_brochure_en.pdf (see website) -->
        <motor forcelimited="false" joint="iiwa14_joint_1" name="iiwa14_torq_j1"/>
        <motor forcelimited="false" joint="iiwa14_joint_2" name="iiwa14_torq_j2"/>
        <motor forcelimited="false" joint="iiwa14_joint_3" name="iiwa14_torq_j3"/>
        <motor forcelimited="false" joint="iiwa14_joint_4" name="iiwa14_torq_j4"/>
        <motor forcelimited="false" joint="iiwa14_joint_5" name="iiwa14_torq_j5"/>
        <motor forcelimited="false" joint="iiwa14_joint_6" name="iiwa14_torq_j6"/>
        <motor forcelimited="false" joint="iiwa14_joint_7" name="iiwa14_torq_j7"/>
    </actuator>    
</mujoco>
